2024-12-28 20:57:17,983 INFO    MainThread:153260 [wandb_setup.py:_flush():68] Current SDK version is 0.19.1
2024-12-28 20:57:17,984 INFO    MainThread:153260 [wandb_setup.py:_flush():68] Configure stats pid to 153260
2024-12-28 20:57:17,984 INFO    MainThread:153260 [wandb_setup.py:_flush():68] Loading settings from /home/picarib/.config/wandb/settings
2024-12-28 20:57:17,984 INFO    MainThread:153260 [wandb_setup.py:_flush():68] Loading settings from /home/picarib/Projects/TangleNAS/wandb/settings
2024-12-28 20:57:17,984 INFO    MainThread:153260 [wandb_setup.py:_flush():68] Loading settings from environment variables
2024-12-28 20:57:17,984 INFO    MainThread:153260 [wandb_init.py:_log_setup():528] Logging user logs to /home/picarib/Projects/TangleNAS/wandb/run-20241228_205717-j16fuotl/logs/debug.log
2024-12-28 20:57:17,984 INFO    MainThread:153260 [wandb_init.py:_log_setup():529] Logging internal logs to /home/picarib/Projects/TangleNAS/wandb/run-20241228_205717-j16fuotl/logs/debug-internal.log
2024-12-28 20:57:17,984 INFO    MainThread:153260 [wandb_init.py:init():644] calling init triggers
2024-12-28 20:57:17,984 INFO    MainThread:153260 [wandb_init.py:init():650] wandb.init called with sweep_config: {}
config: {}
2024-12-28 20:57:17,984 INFO    MainThread:153260 [wandb_init.py:init():680] starting backend
2024-12-28 20:57:17,984 INFO    MainThread:153260 [wandb_init.py:init():684] sending inform_init request
2024-12-28 20:57:17,990 INFO    MainThread:153260 [backend.py:_multiprocessing_setup():104] multiprocessing start_methods=fork,spawn,forkserver, using: spawn
2024-12-28 20:57:17,991 INFO    MainThread:153260 [wandb_init.py:init():697] backend started and connected
2024-12-28 20:57:17,992 INFO    MainThread:153260 [wandb_init.py:init():790] updated telemetry
2024-12-28 20:57:17,996 INFO    MainThread:153260 [wandb_init.py:init():822] communicating run to backend with 90.0 second timeout
2024-12-28 20:57:18,305 ERROR   MainThread:153260 [wandb_init.py:init():849] encountered error: failed to upsert bucket: returned error 404 Not Found: {"errors":[{"message":"entity your-team not found during upsertBucket","path":["upsertBucket"]}],"data":{"upsertBucket":null}}
2024-12-28 20:57:18,305 ERROR   MainThread:153260 [wandb_init.py:init():1308] error in wandb.init()
Traceback (most recent call last):
  File "/home/picarib/anaconda3/envs/nas_dev/lib/python3.12/site-packages/wandb/sdk/wandb_init.py", line 1298, in init
    return wi.init()
           ^^^^^^^^^
  File "/home/picarib/anaconda3/envs/nas_dev/lib/python3.12/site-packages/wandb/sdk/wandb_init.py", line 855, in init
    raise error
wandb.errors.errors.CommError: failed to upsert bucket: returned error 404 Not Found: {"errors":[{"message":"entity your-team not found during upsertBucket","path":["upsertBucket"]}],"data":{"upsertBucket":null}}
2024-12-28 20:57:18,308 WARNING MsgRouterThr:153260 [router.py:message_loop():75] message_loop has been closed
